Workbook
Name Slicer_Branch: #N/A
Name Slicer_Category: #N/A
Name Slicer_Months__Date: #N/A
Name Slicer_Payment_Method: #N/A

Sheet Dashboard

Sheet Pivot_Tables
A3: Branch | B3: Total Revenue
A4: EASTLANDS | B4: 176604.05 | D4: =A4 -> EASTLANDS | E4: =B4 -> 176604.05
A5: NAIROBI CBD | B5: 175508.51 | D5: =A5 -> NAIROBI CBD | E5: =B5 -> 175508.51 | G5: Total Rev | H5: =SUM(B4:B8) -> 849745.31
A6: NGONG ROAD | B6: 151945.73 | D6: =A6 -> NGONG ROAD | E6: =B6 -> 151945.73
A7: THIKA ROAD | B7: 166520.34 | D7: =A7 -> THIKA ROAD | E7: =B7 -> 166520.34
A8: WESTLANDS | B8: 179166.68 | D8: =A8 -> WESTLANDS | E8: =B8 -> 179166.68
A11: Category | B11: Total Revenue
A12: Bakery | B12: 78728.97 | D12: =A12 -> Bakery | E12: =B12 -> 78728.97 | G12: Max: | H12: =MAX(B12:B17) -> 254618.84
A13: Dairy | B13: 155365.6 | D13: =A13 -> Dairy | E13: =B13 -> 155365.6 | H13: =_xlfn.XLOOKUP(H12,B12:B17,A12:A17,0,0) -> Household
A14: Grocery | B14: 81580.61 | D14: =A14 -> Grocery | E14: =B14 -> 81580.61
A15: Household | B15: 254618.84 | D15: =A15 -> Household | E15: =B15 -> 254618.84
A16: Personal Care | B16: 73813.33 | D16: =A16 -> Personal Care | E16: =B16 -> 73813.33
A17: Produce | B17: 205637.96 | D17: =A17 -> Produce | E17: =B17 -> 205637.96
A20: Item | B20: Total Revenue
A21: Milk | B21: 155365.6 | D21: =A21 -> Milk | E21: =B21 -> 155365.6
A22: Sugar | B22: 116690.81 | D22: =A22 -> Sugar | E22: =B22 -> 116690.81
A23: Salt | B23: 84557.08 | D23: =A23 -> Salt | E23: =B23 -> 84557.08
A24: Rice | B24: 82662.29 | D24: =A24 -> Rice | E24: =B24 -> 82662.29
A25: Cooking Oil | B25: 81580.61 | D25: =A25 -> Cooking Oil | E25: =B25 -> 81580.61
A26: Bread | B26: 78728.97 | D26: =A26 -> Bread | E26: =B26 -> 78728.97
A27: Eggs | B27: 53577.87 | D27: =A27 -> Eggs | E27: =B27 -> 53577.87
A28: Shampoo | B28: 36964.91 | D28: =A28 -> Shampoo | E28: =B28 -> 36964.91
A29: Toothpaste | B29: 36848.42 | D29: =A29 -> Toothpaste | E29: =B29 -> 36848.42
A30: Tomatoes | B30: 35303.53 | D30: =A30 -> Tomatoes | E30: =B30 -> 35303.53
A31: Onions | B31: 34094.27 | D31: =A31 -> Onions | E31: =B31 -> 34094.27
A32: Tissue | B32: 29198.61 | D32: =A32 -> Tissue | E32: =B32 -> 29198.61
A33: Laundry Soap | B33: 24172.34 | D33: =A33 -> Laundry Soap | E33: =B33 -> 24172.34
A38: Branch | B38: Payment_Method | C38: Total Revenue
A39: EASTLANDS | B39: Card | C39: 76356.33
B40: Cash | C40: 52337.45
B41: Mobile | C41: 47910.27
A42: NAIROBI CBD | B42: Card | C42: 69261.88
B43: Mobile | C43: 56027.26
B44: Cash | C44: 50219.37
A45: NGONG ROAD | B45: Cash | C45: 61514.67
B46: Card | C46: 49811.77
B47: Mobile | C47: 40619.29
A48: THIKA ROAD | B48: Cash | C48: 63298.42
B49: Mobile | C49: 51920.8
B50: Card | C50: 51301.12
...

Sheet Clean_Data
A1: Date | B1: Receipt_ID | C1: Branch | D1: Item | E1: Category | F1: Quantity | G1: Unit_Price | H1: Payment_Method | I1: Revenue
A2: 45619 | B2: R1028 | C2: NAIROBI CBD | D2: Onions | E2: {=_xlfn.XLOOKUP(D2,_xlfn.ANCHORARRAY('Item_ Master'!$A$2),'Item_ Master'!$B$2:$B$14,0,0)} -> Produce | F2: 5 | G2: 184.69 | H2: Cash | I2: =F2*$G$2 -> 923.45
A3: 45571 | B3: R1022 | C3: NGONG ROAD | D3: Cooking Oil | E3: {=_xlfn.XLOOKUP(D3,_xlfn.ANCHORARRAY('Item_ Master'!$A$2),'Item_ Master'!$B$2:$B$14,0,0)} -> Grocery | F3: 1 | G3: 66.39 | H3: Cash | I3: =F3*G3 -> 66.39
A4: 45600 | B4: R1006 | C4: NGONG ROAD | D4: Bread | E4: {=_xlfn.XLOOKUP(D4,_xlfn.ANCHORARRAY('Item_ Master'!$A$2),'Item_ Master'!$B$2:$B$14,0,0)} -> Bakery | F4: 9 | G4: 280.74 | H4: Card | I4: =F4*G4 -> 2526.66
A5: 45295 | B5: R1194 | C5: WESTLANDS | D5: Tomatoes | E5: {=_xlfn.XLOOKUP(D5,_xlfn.ANCHORARRAY('Item_ Master'!$A$2),'Item_ Master'!$B$2:$B$14,0,0)} -> Produce | F5: 7 | G5: 237.14 | H5: Cash | I5: =F5*G5 -> 1659.98
A6: 45464 | B6: R1026 | C6: NAIROBI CBD | D6: Cooking Oil | E6: {=_xlfn.XLOOKUP(D6,_xlfn.ANCHORARRAY('Item_ Master'!$A$2),'Item_ Master'!$B$2:$B$14,0,0)} -> Grocery | F6: 2 | G6: 247.44 | H6: Card | I6: =F6*G6 -> 494.88
A7: 45314 | B7: R1186 | C7: THIKA ROAD | D7: Laundry Soap | E7: {=_xlfn.XLOOKUP(D7,_xlfn.ANCHORARRAY('Item_ Master'!$A$2),'Item_ Master'!$B$2:$B$14,0,0)} -> Household | F7: 1 | G7: 585.21 | H7: Card | I7: =F7*G7 -> 585.21
A8: 45442 | B8: R1160 | C8: NGONG ROAD | D8: Rice | E8: {=_xlfn.XLOOKUP(D8,_xlfn.ANCHORARRAY('Item_ Master'!$A$2),'Item_ Master'!$B$2:$B$14,0,0)} -> Produce | F8: 10 | G8: 155.76 | H8: Cash | I8: =F8*G8 -> 1557.6
A9: 45408 | B9: R1197 | C9: EASTLANDS | D9: Milk | E9: {=_xlfn.XLOOKUP(D9,_xlfn.ANCHORARRAY('Item_ Master'!$A$2),'Item_ Master'!$B$2:$B$14,0,0)} -> Dairy | F9: 4 | G9: 526.57 | H9: Card | I9: =F9*G9 -> 2106.28
A10: 45617 | B10: R1093 | C10: WESTLANDS | D10: Rice | E10: {=_xlfn.XLOOKUP(D10,_xlfn.ANCHORARRAY('Item_ Master'!$A$2),'Item_ Master'!$B$2:$B$14,0,0)} -> Produce | F10: 6 | G10: 165.23 | H10: Card | I10: =F10*G10 -> 991.38
A11: 45328 | B11: R1155 | C11: WESTLANDS | D11: Laundry Soap | E11: {=_xlfn.XLOOKUP(D11,_xlfn.ANCHORARRAY('Item_ Master'!$A$2),'Item_ Master'!$B$2:$B$14,0,0)} -> Household | F11: 4 | G11: 139.87 | H11: Card | I11: =F11*G11 -> 559.48
A12: 45619 | B12: R1176 | C12: NGONG ROAD | D12: Sugar | E12: {=_xlfn.XLOOKUP(D12,_xlfn.ANCHORARRAY('Item_ Master'!$A$2),'Item_ Master'!$B$2:$B$14,0,0)} -> Household | F12: 6 | G12: 513.57 | H12: Cash | I12: =F12*G12 -> 3081.42
A13: 45308 | B13: R1080 | C13: THIKA ROAD | D13: Sugar | E13: {=_xlfn.XLOOKUP(D13,_xlfn.ANCHORARRAY('Item_ Master'!$A$2),'Item_ Master'!$B$2:$B$14,0,0)} -> Household | F13: 2 | G13: 166.04 | H13: Mobile | I13: =F13*G13 -> 332.08
A14: 45453 | B14: R1054 | C14: THIKA ROAD | D14: Cooking Oil | E14: {=_xlfn.XLOOKUP(D14,_xlfn.ANCHORARRAY('Item_ Master'!$A$2),'Item_ Master'!$B$2:$B$14,0,0)} -> Grocery | F14: 8 | G14: 128.58 | H14: Cash | I14: =F14*G14 -> 1028.64
... A501: 45361 | B501: R1199 | C501: NGONG ROAD | D501: Toothpaste | E501: {=_xlfn.XLOOKUP(D501,_xlfn.ANCHORARRAY('Item_ Master'!$A$2),'Item_ Master'!$B$2:$B$14,0,0)} -> Personal Care | F501: 1 | G501: 145.56 | H501: Cash | I501: =F501*G501 -> 145.56

Sheet Item_ Master
A1: Item | B1: Category
A2: {=_xlfn.UNIQUE('Clean_Data'!D2:$D$501,FALSE)} -> Onions | B2: Produce
A3: Cooking Oil | B3: Grocery
A4: Bread | B4: Bakery
A5: Tomatoes | B5: Produce
A6: Laundry Soap | B6: Household
A7: Rice | B7: Produce
A8: Milk | B8: Dairy
A9: Sugar | B9: Household
A10: Eggs | B10: Produce
A11: Shampoo | B11: Personal Care
A12: Tissue | B12: Household
A13: Salt | B13: Household
A14: Toothpaste | B14: Personal Care

Sheet Raw_Data
A1: Date | B1: Receipt_ID | C1: Branch | D1: Item | E1: Category | F1: Quantity | G1: Unit_Price | H1: Payment_Method
A2: 45619 | B2: R1028 | C2: Nairobi CBD | D2: Onions | E2: Produce | F2: 5 | G2: 184.69 | H2: Cash
A3: 45571 | B3: R1022 | C3: Ngong Road | D3: Oil 2L | E3: Grocery | F3: 1 | G3: 66.39 | H3: Cash
A4: 45600 | B4: R1006 | C4: Ngong Road | D4: brown bread | E4: Bakery | F4: 9 | G4: 280.74 | H4: Card
A5: 45295 | B5: R1194 | C5: Westlands | D5: Tomatoes | E5: Produce | F5: 7 | G5: 237.14 | H5: Cash
A6: 45464 | B6: R1026 | C6: Nairobi CBD | D6: Cooking Oil | E6: Grocery | F6: 2 | G6: 247.44 | H6: Card
A7: 45314 | B7: R1186 | C7: Thika Road | D7: Laundry Soap | F7: 2 | G7: 585.21 | H7: Card
A8: 45442 | B8: R1160 | C8: Ngong Road | D8: Rice 5kg | F8: 10 | G8: 155.76 | H8: Cash
A9: 45408 | B9: R1197 | C9: Eastlands | D9: MILK | E9: Dairy | F9: 4 | G9: 526.57 | H9: Card
A10: 45617 | B10: R1093 | C10: Westlands | D10: Rice 5kg | E10: Grocery | F10: 6 | G10: 165.23 | H10: Card
A11: 45328 | B11: R1155 | C11: Westlands | D11: Laundry Soap | E11: Household | F11: 4 | G11: 139.87 | H11: Card
A12: 45619 | B12: R1176 | C12: Ngong Road | D12: Sugar | E12: Grocery | F12: 6 | G12: 513.57 | H12: Cash
A13: 45308 | B13: R1080 | C13: Thika Road | D13: Sugar 1kg | E13: Grocery | F13: 2 | G13: 166.04 | H13: Mobile
A14: 45453 | B14: R1054 | C14: Thika Road | D14: Cooking Oil | E14: Grocery | F14: 8 | G14: 128.58 | H14: Cash
A15: 45579 | B15: R1137 | C15: Eastlands | D15: Onions | E15: Produce | F15: 10 | G15: 285.64 | H15: Mobile
A16: 45404 | B16: R1035 | C16: Ngong Road | D16: Eggs Tray | E16: Dairy | F16: 2 | G16: 465.68 | H16: Cash
A17: 45373 | B17: R1174 | C17: Thika Road | D17: Shampoo | E17: Personal Care | F17: 2 | G17: 261.62 | H17: Mobile
A18: 45562 | B18: R1064 | C18: Ngong Road | D18: Milk | E18: Dairy | F18: 2 | G18: 424.94 | H18: Mobile
A19: 45620 | B19: R1087 | C19: Nairobi CBD | D19: SUGAR | E19: Grocery | F19: 7 | G19: 136.99 | H19: Cash
A20: 45426 | B20: R1128 | C20: Westlands | D20: Soap | E20: Household | F20: 2 | G20: 528.79 | H20: Card
... A26: 45451 | B26: R1102 | C26: Eastlands | D26: Eggs | E26: Dairy | F26: 9 | G26: 298.32 | H26: Cash
A27: 45465 | B27: R1005 | C27: Ngong Road | D27: Laundry Soap | F27: 4 | G27: 373.64 | H27: Cash
A28: 45615 | B28: R1015 | C28: Westlands | D28: MILK | E28: Dairy | F28: 1 | G28: 522.8 | H28: Cash
A29: 45434 | B29: R1171 | C29: Thika Road | D29: brown bread | E29: Bakery | F29: 9 | G29: 122.77 | H29: Mobile
A30: 45416 | B30: R1200 | C30: Thika Road | D30: Oil 2L | E30: Grocery | F30: 4 | G30: 101.88 | H30: Mobile
A31: 45508 | B31: R1105 | C31: Thika Road | D31: Onions | F31: 1 | G31: 420.35 | H31: Mobile
A32: 45498 | B32: R1186 | C32: Eastlands | D32: Milk 1L | E32: Dairy | F32: 4 | G32: 155.37 | H32: Mobile
A33: 45508 | B33: R1046 | C33: Eastlands | D33: Eggs | E33: Dairy | F33: 4 | G33: 530.97 | H33: Cash
A34: 45573 | B34: R1025 | C34: Nairobi CBD | D34: Salt | E34: Grocery | F34: 9 | G34: 509.82 | H34: Cash
A35: 45413 | B35: R1042 | C35: Thika Road | D35: Eggs Tray | E35: Dairy | F35: 8 | G35: 167.56 | H35: Card
A36: 45376 | B36: R1097 | C36: Nairobi CBD | D36: Cooking Oil | E36: Grocery | F36: 5 | G36: 559.58 | H36: Card
A37: 45576 | B37: R1169 | C37: Thika Road | D37: Bread | E37: Bakery | F37: 4 | G37: 213.19 | H37: Cash
A38: 45569 | B38: R1015 | C38: Eastlands | D38: milk | E38: Dairy | F38: 1 | G38: 371.3 | H38: Mobile
A39: 45563 | B39: R1040 | C39: Nairobi CBD | D39: Soap | E39: Household | F39: 2 | G39: 518.24 | H39: Cash
A40: 45412 | B40: R1103 | C40: Nairobi CBD | D40: Toothpaste | E40: Personal Care | F40: 4 | G40: 368.41 | H40: Cash
A41: 45506 | B41: R1168 | C41: Ngong Road | D41: Toothpaste | E41: Personal Care | F41: 9 | G41: 224 | H41: Card
A42: 45452 | B42: R1061 | C42: Eastlands | D42: Cooking Oil | E42: Grocery | F42: 3 | G42: 419.43 | H42: Card
A43: 45329 | B43: R1002 | C43: Thika Road | D43: Shampoo | E43: Personal Care | F43: 10 | G43: 597.85 | H43: Cash
... A48: 45318 | B48: R1023 | C48: Thika Road | D48: Sugar 1kg | E48: Grocery | F48: 1 | G48: 51.95 | H48: Cash
A49: 45426 | B49: R1041 | C49: Thika Road | D49: Laundry Soap | F49: 7 | G49: 358.5 | H49: Cash
...
